Workbook

Sheet 0 Anleitung
B2: Valtix Basismodell – Eingabevorlage
B3: Bitte nur die gelb hinterlegten Felder ausfüllen und die Datei anschließend zurücksenden.
B6: SO GEHEN SIE VOR
A7: 1. | B7: Blatt „1 Stammdaten“ ausfüllen – dort legen Sie unter anderem fest, wie Ihre Leistungseinheit heißt (z. B. Bon, Waschgang, Beratertag, Monteurstunde).
A8: 2. | B8: Blatt „2 GuV“ – Erlöse und Kosten je Monat eintragen. Alle Beträge netto, ohne Umsatzsteuer.
A9: 3. | B9: Blatt „3 Mengen & Operativ“ – Stückzahlen, Mitarbeitende und Ihre operativen Kennzahlen.
A10: 4. | B10: Blatt „4 Liquidität & Bilanz“ – Kontostand, Forderungen und Eigenkapital je Monatsende.
A11: 5. | B11: Blatt „5 Zielwerte“ – welche Werte gelten für Sie als Ziel? Daraus entsteht die Ampel im Bericht.
A12: 6. | B12: Blatt „6 Prüfung“ öffnen: Steht dort überall „OK“, ist die Datei vollständig.
B14: FARBLEGENDE
A15: Gelb | B15: Eingabefeld – hier tragen Sie Ihre Werte ein (blaue Schrift).
A16: Grau-blau | B16: Wird automatisch berechnet – bitte nicht überschreiben.
A17: Weiß | B17: Beschriftung.
B19: WICHTIGE HINWEISE
A20: • | B20: Alle Beträge bitte als positive Zahl eintragen – auch Kosten. Die Vorzeichen setzen wir.
A21: • | B21: Alle Beträge netto (ohne Umsatzsteuer).
A22: • | B22: Monate, für die noch keine Zahlen vorliegen, einfach leer lassen.
A23: • | B23: Nicht zutreffende Positionen leer lassen – nicht löschen, damit die Struktur erhalten bleibt.
A24: • | B24: Zeilen mit „(optional)“ können entfallen; der Bericht wird dann ohne diese Kennzahl erstellt.
A25: • | B25: Bei Fragen zu einer Position: mit der Maus über die Beschriftung fahren – dort stehen Hinweise.
B27: WAS SIE ZURÜCKBEKOMMEN
B28: Das monatliche Management-Cockpit: Dashboard mit Ergebnisbrücke, Kostenanalyse, Vormonats- und Halbjahresvergleich, KPI-Ampel, Break-Even-Rechnung und Maßnahmenkatalog.

Sheet 1 Stammdaten
A1: 1 Stammdaten
A2: Grundangaben zum Unternehmen und zur Berichtsperiode.
A4: Angabe | B4: Ihre Eingabe | C4: Beispiel / Hinweis
A5: Firmenname | C5: Muster Dienstleistungs GmbH
A6: Rechtsform | C6: GmbH / e. K. / GbR / UG
A7: Branche / Tätigkeit | C7: Gebäudereinigung, Gastronomie, Handwerk …
A8: Berichtsjahr | C8: 2026
A9: Berichtsmonat (aktueller Monat) | C9: Juli
A10: Ansprechpartner | C10: Vorname Nachname
A11: E-Mail für Rückfragen | C11: name@firma.de
A13: Leistungseinheit
A14: Bezeichnung Ihrer Leistungseinheit | C14: Bon / Waschgang / Beratertag / Monteurstunde
A15: Bezeichnung im Plural | C15: Bons / Waschgänge / Beratertage
A17: Hinweis: Alle Beträge in dieser Datei netto (ohne Umsatzsteuer) und als positive Zahl eintragen.

Sheet 2 GuV
A1: 2 Gewinn- und Verlustrechnung
A2: Alle Beträge netto und als positive Zahl. Nicht zutreffende Zeilen leer lassen.
A4: Position | B4: Januar | C4: Februar | D4: März | E4: April | F4: Mai | G4: Juni | H4: Juli | I4: August | J4: September | K4: Oktober | L4: November | M4: Dezember
A5: ERLÖSE
A6: Erlöse Hauptleistung
A7: Erlöse Nebenleistung 1 (optional)
A8: Erlöse Nebenleistung 2 (optional)
A9: Warenverkauf / weiterberechnetes Material (optional)
A10: Σ Umsatzerlöse | B10: =SUM(B6:B9) -> 0 | C10: =SUM(C6:C9) -> 0 | D10: =SUM(D6:D9) -> 0 | E10: =SUM(E6:E9) -> 0 | F10: =SUM(F6:F9) -> 0 | G10: =SUM(G6:G9) -> 0 | H10: =SUM(H6:H9) -> 0 | I10: =SUM(I6:I9) -> 0 | ... M10: =SUM(M6:M9) -> 0
A11: Sonstige betriebliche Erträge
A12: Σ Gesamtleistung | B12: =B10+B11 -> 0 | C12: =C10+C11 -> 0 | D12: =D10+D11 -> 0 | E12: =E10+E11 -> 0 | F12: =F10+F11 -> 0 | G12: =G10+G11 -> 0 | H12: =H10+H11 -> 0 | I12: =I10+I11 -> 0 | ... M12: =M10+M11 -> 0
A14: VARIABLE KOSTEN (steigen mit jeder zusätzlichen Leistungseinheit)
A15: Wareneinsatz / Materialaufwand
A16: Fremdleistungen / Subunternehmer
A17: Leistungsabhängige Löhne (optional)
A18: Energie mengenabhängig (optional)
A19: Provisionen / Plattformgebühren (optional)
A20: Verpackung / Transport (optional)
A21: Sonstige variable Kosten (optional)
A22: Σ Variable Kosten gesamt | B22: =SUM(B15:B21) -> 0 | C22: =SUM(C15:C21) -> 0 | D22: =SUM(D15:D21) -> 0 | E22: =SUM(E15:E21) -> 0 | F22: =SUM(F15:F21) -> 0 | G22: =SUM(G15:G21) -> 0 | H22: =SUM(H15:H21) -> 0 | I22: =SUM(I15:I21) -> 0 | ... M22: =SUM(M15:M21) -> 0
A23: Σ Deckungsbeitrag | B23: =B12-B22 -> 0 | C23: =C12-C22 -> 0 | D23: =D12-D22 -> 0 | E23: =E12-E22 -> 0 | F23: =F12-F22 -> 0 | G23: =G12-G22 -> 0 | H23: =H12-H22 -> 0 | I23: =I12-I22 -> 0 | ... M23: =M12-M22 -> 0
A24: Deckungsbeitragsquote | B24: =IFERROR(B23/B12*100,"") | C24: =IFERROR(C23/C12*100,"") | D24: =IFERROR(D23/D12*100,"") | E24: =IFERROR(E23/E12*100,"") | F24: =IFERROR(F23/F12*100,"") | G24: =IFERROR(G23/G12*100,"") | H24: =IFERROR(H23/H12*100,"") | I24: =IFERROR(I23/I12*100,"") | ... M24: =IFERROR(M23/M12*100,"")
A26: FIXKOSTEN (fallen unabhängig von der Menge an)
A27: Personalaufwand (inkl. Arbeitgeberanteil)
A28: Miete & Nebenkosten
A29: Energie (Grundgebühren, Heizung)
A30: Fahrzeuge / Fuhrpark
A31: Wartung, Reparatur & Instandhaltung
A32: Versicherungen & Beiträge (inkl. Berufsgenossenschaft)
A33: IT, Software & Kommunikation
A34: Marketing & Vertrieb
A35: Beratung (Steuerberatung, Recht)
A36: Sonstige betriebliche Aufwendungen
A37: Σ Fixkosten gesamt (ohne Abschreibungen) | B37: =SUM(B27:B36) -> 0 | C37: =SUM(C27:C36) -> 0 | D37: =SUM(D27:D36) -> 0 | E37: =SUM(E27:E36) -> 0 | F37: =SUM(F27:F36) -> 0 | G37: =SUM(G27:G36) -> 0 | H37: =SUM(H27:H36) -> 0 | I37: =SUM(I27:I36) -> 0 | ... M37: =SUM(M27:M36) -> 0
A38: Σ EBITDA | B38: =B23-B37 -> 0 | C38: =C23-C37 -> 0 | D38: =D23-D37 -> 0 | E38: =E23-E37 -> 0 | F38: =F23-F37 -> 0 | G38: =G23-G37 -> 0 | H38: =H23-H37 -> 0 | I38: =I23-I37 -> 0 | ... M38: =M23-M37 -> 0
A40: ABSCHREIBUNGEN UND ZINSEN
A41: Abschreibungen (AfA)
A42: Σ EBIT | B42: =B38-B41 -> 0 | C42: =C38-C41 -> 0 | D42: =D38-D41 -> 0 | E42: =E38-E41 -> 0 | F42: =F38-F41 -> 0 | G42: =G38-G41 -> 0 | H42: =H38-H41 -> 0 | I42: =I38-I41 -> 0 | ... M42: =M38-M41 -> 0
A43: Zinsaufwand (positiv eintragen)
A44: Zinserträge (optional)
...

Sheet 3 Mengen & Operativ
A1: 3 Mengen und operative Kennzahlen
A2: Die Leistungseinheit haben Sie in Blatt „1 Stammdaten“ festgelegt.
A4: Kennzahl | B4: Januar | C4: Februar | D4: März | E4: April | F4: Mai | G4: Juni | H4: Juli | I4: August | J4: September | K4: Oktober | L4: November | M4: Dezember
A5: MENGENGERÜST
A6: Anzahl Leistungseinheiten
A7: Kapazität (mögliche Einheiten, optional)
A8: Auslastung | B8: =IFERROR(B6/B7*100,"") | C8: =IFERROR(C6/C7*100,"") | D8: =IFERROR(D6/D7*100,"") | E8: =IFERROR(E6/E7*100,"") | F8: =IFERROR(F6/F7*100,"") | G8: =IFERROR(G6/G7*100,"") | H8: =IFERROR(H6/H7*100,"") | I8: =IFERROR(I6/I7*100,"") | ... M8: =IFERROR(M6/M7*100,"")
A9: Ø Erlös je Leistungseinheit | B9: =IFERROR('2 GuV'!B10/B6,"") | C9: =IFERROR('2 GuV'!C10/C6,"") | D9: =IFERROR('2 GuV'!D10/D6,"") | E9: =IFERROR('2 GuV'!E10/E6,"") | F9: =IFERROR('2 GuV'!F10/F6,"") | G9: =IFERROR('2 GuV'!G10/G6,"") | H9: =IFERROR('2 GuV'!H10/H6,"") | I9: =IFERROR('2 GuV'!I10/I6,"") | ... M9: =IFERROR('2 GuV'!M10/M6,"")
A10: Deckungsbeitrag je Leistungseinheit | B10: =IFERROR('2 GuV'!B23/B6,"") | C10: =IFERROR('2 GuV'!C23/C6,"") | D10: =IFERROR('2 GuV'!D23/D6,"") | E10: =IFERROR('2 GuV'!E23/E6,"") | F10: =IFERROR('2 GuV'!F23/F6,"") | G10: =IFERROR('2 GuV'!G23/G6,"") | H10: =IFERROR('2 GuV'!H23/H6,"") | I10: =IFERROR('2 GuV'!I23/I6,"") | ... M10: =IFERROR('2 GuV'!M23/M6,"")
A12: PERSONAL
A13: Mitarbeitende (Köpfe)
A14: Vollzeitäquivalente (VZÄ)
A15: Bezahlte Stunden gesamt (optional)
A16: Produktivstundenquote | B16: =IFERROR(B6/B15*100,"") | C16: =IFERROR(C6/C15*100,"") | D16: =IFERROR(D6/D15*100,"") | E16: =IFERROR(E6/E15*100,"") | F16: =IFERROR(F6/F15*100,"") | G16: =IFERROR(G6/G15*100,"") | H16: =IFERROR(H6/H15*100,"") | I16: =IFERROR(I6/I15*100,"") | ... M16: =IFERROR(M6/M15*100,"")
A17: Krankenstand in % (optional)
A18: Austritte im Monat (optional)
A20: KUNDEN & AUFTRÄGE
A21: Aktive Kunden / Objekte / Mandate
A22: Neukunden bzw. Neuaufträge im Monat
A23: Auftragsbestand / Vertragsvolumen (optional)
A24: Reklamationen (optional)
A26: EIGENE KENNZAHLEN (bis zu vier – Bezeichnung in Spalte A selbst eintragen)
A27: Eigene Kennzahl 1 …
A28: Eigene Kennzahl 2 …
A29: Eigene Kennzahl 3 …
A30: Eigene Kennzahl 4 …

Sheet 4 Liquidität & Bilanz
A1: 4 Liquidität und Bilanz
A2: Jeweils Stand zum Monatsende. Für die Ampel genügen die ersten vier Zeilen.
A4: Position | B4: Januar | C4: Februar | D4: März | E4: April | F4: Mai | G4: Juni | H4: Juli | I4: August | J4: September | K4: Oktober | L4: November | M4: Dezember
A5: LIQUIDITÄT
A6: Liquide Mittel (Bank + Kasse)
A7: Offene Forderungen (Debitoren)
A8: Kurzfristige Verbindlichkeiten
A9: Liquidität 1. Grades | B9: =IFERROR(B6/B8*100,"") | C9: =IFERROR(C6/C8*100,"") | D9: =IFERROR(D6/D8*100,"") | E9: =IFERROR(E6/E8*100,"") | F9: =IFERROR(F6/F8*100,"") | G9: =IFERROR(G6/G8*100,"") | H9: =IFERROR(H6/H8*100,"") | I9: =IFERROR(I6/I8*100,"") | ... M9: =IFERROR(M6/M8*100,"")
A10: Debitorenlaufzeit (DSO, Tage) | B10: =IFERROR(B7/'2 GuV'!B10*30,"") | C10: =IFERROR(C7/'2 GuV'!C10*30,"") | D10: =IFERROR(D7/'2 GuV'!D10*30,"") | E10: =IFERROR(E7/'2 GuV'!E10*30,"") | F10: =IFERROR(F7/'2 GuV'!F10*30,"") | G10: =IFERROR(G7/'2 GuV'!G10*30,"") | H10: =IFERROR(H7/'2 GuV'!H10*30,"") | I10: =IFERROR(I7/'2 GuV'!I10*30,"") | ... M10: =IFERROR(M7/'2 GuV'!M10*30,"")
A12: BILANZ (optional – falls nicht verfügbar, leer lassen)
A13: Eigenkapital
A14: Bilanzsumme
A15: Eigenkapitalquote | B15: =IFERROR(B13/B14*100,"") | C15: =IFERROR(C13/C14*100,"") | D15: =IFERROR(D13/D14*100,"") | E15: =IFERROR(E13/E14*100,"") | F15: =IFERROR(F13/F14*100,"") | G15: =IFERROR(G13/G14*100,"") | H15: =IFERROR(H13/H14*100,"") | I15: =IFERROR(I13/I14*100,"") | ... M15: =IFERROR(M13/M14*100,"")
A16: Finanzverbindlichkeiten (Darlehen, Kontokorrent)
A17: Anlagevermögen (optional)

Sheet 5 Zielwerte
A1: 5 Zielwerte für die Ampel
A2: Grün = Ziel erreicht · Gelb = bis 10 % verfehlt · Rot = mehr als 10 % verfehlt.
A4: Kennzahl | B4: Zielwert | C4: Richtung | D4: Hinweis
A5: Umsatzerlöse je Monat | C5: höher ist besser | D5: Ihr Monatsziel.
A6: EBT-Marge | C6: höher ist besser | D6: In Prozent, z. B. 6,0.
A7: Deckungsbeitragsquote | C7: höher ist besser | D7: In Prozent.
A8: Liquide Mittel (Mindestbestand) | C8: höher ist besser | D8: Unter welchen Betrag darf der Kontostand nicht fallen?
A9: Eigenkapitalquote | C9: höher ist besser | D9: In Prozent (optional).
A10: Debitorenlaufzeit (DSO) | C10: niedriger ist besser | D10: In Tagen.
A11: Auslastung | C11: höher ist besser | D11: In Prozent (optional).
A12: Aktive Kunden / Objekte | C12: höher ist besser
A13: Neukunden je Monat | C13: höher ist besser
A14: Eigene Kennzahl 1 | D14: Bezeichnung aus Blatt 3 übernehmen.
A15: Eigene Kennzahl 2
A16: Eigene Kennzahl 3
A17: Eigene Kennzahl 4

Sheet 6 Prüfung
A1: 6 Prüfung der Vollständigkeit
A2: Steht in Spalte B überall „OK“, kann die Datei zurückgesendet werden.
A4: Prüfpunkt | B4: Status | C4: Hinweis bei Fehler
A5: Stammdaten ausgefüllt | B5: =IF(COUNTA('1 Stammdaten'!B5:B15)>=8,"OK","unvollständig") -> unvollständig | C5: Firmenname, Berichtsmonat und Leistungseinheit werden benötigt.
A6: Umsatzerlöse erfasst | B6: =IF(SUM('2 GuV'!B10:M10)>0,"OK","fehlt") -> fehlt | C6: In Blatt 2 sind keine Erlöse eingetragen.
A7: Kosten erfasst | B7: =IF(SUM('2 GuV'!B37:M37)+SUM('2 GuV'!B22:M22)>0,"OK","fehlt") -> fehlt | C7: Weder variable noch fixe Kosten eingetragen.
A8: Mengen erfasst | B8: =IF(SUM('3 Mengen & Operativ'!B6:M6)>0,"OK","fehlt") -> fehlt | C8: Ohne Mengen sind Break-Even und Preis je Einheit nicht berechenbar.
A9: Liquide Mittel erfasst | B9: =IF(COUNT('4 Liquidität & Bilanz'!B6:M6)>0,"OK","fehlt") -> fehlt | C9: Für die Liquiditätsampel erforderlich.
A10: Zielwerte gesetzt | B10: =IF(COUNT('5 Zielwerte'!B5:B17)>=4,"OK","unvollständig") -> unvollständig | C10: Mindestens vier Zielwerte eintragen, sonst entfällt die Ampel.
A11: Plausibilität: Kosten kleiner als Erlöse? | B11: =IF(SUM('2 GuV'!B10:M10)>SUM('2 GuV'!B22:M22),"OK","bitte prüfen") -> bitte prüfen | C11: Variable Kosten übersteigen den Umsatz – meist ein Eingabefehler.
A12: Anzahl befüllter Monate | B12: =COUNT('2 GuV'!B6:M6)&" Monat(e) erfasst" -> 0 Monat(e) erfasst | C12: Für Halbjahresvergleich werden mindestens sechs Monate benötigt.
A14: Wenn alles auf OK steht: Datei speichern und an Valtix zurücksenden.
